<?xml version="1.0" encoding="UTF-8"?>
<testsuite name="tests.pearlpc.PEARLPCTests-20210726161813" tests="1" file="tests/pearlpc.py" time="20.633" timestamp="2021-07-26T16:18:46" failures="1" errors="0" skipped="0">
	<testcase classname="tests.pearlpc.PEARLPCTests" name="test_WHEN_pressure_set_THEN_pressure_readback_correctly" time="20.633" timestamp="2021-07-26T16:18:46" file="tests\pearlpc.py" line="38">
		<failure type="AssertionError" message="Expected PV, 'TE:NDLT1544:PEARLPC_01:PRESSURE.SEVR' to have value 'NO_ALARM' (type: 'str').
Final PV value was 'INVALID' (type: 'str')"><![CDATA[Traceback (most recent call last):
  File "C:\Instrument\Apps\EPICS\support\PearlPressureContainer\master\system_tests\tests\pearlpc.py", line 39, in test_WHEN_pressure_set_THEN_pressure_readback_correctly
    self.ca.assert_setting_setpoint_sets_readback(1000, "PRESSURE")
  File "C:\Instrument\Apps\EPICS\support\IocTestFramework\master\utils\channel_access.py", line 556, in assert_setting_setpoint_sets_readback
    self.assert_that_pv_alarm_is(readback_pv, expected_alarm, timeout=timeout)
  File "C:\Instrument\Apps\EPICS\support\IocTestFramework\master\utils\channel_access.py", line 529, in assert_that_pv_alarm_is
    return self.assert_that_pv_is("{}.SEVR".format(pv_no_field), alarm, timeout=timeout)
  File "C:\Instrument\Apps\EPICS\support\IocTestFramework\master\utils\channel_access.py", line 269, in assert_that_pv_is
    return self.assert_that_pv_value_causes_func_to_return_true(
  File "C:\Instrument\Apps\EPICS\support\IocTestFramework\master\utils\channel_access.py", line 248, in assert_that_pv_value_causes_func_to_return_true
    raise AssertionError(err)
AssertionError: Expected PV, 'TE:NDLT1544:PEARLPC_01:PRESSURE.SEVR' to have value 'NO_ALARM' (type: 'str').
Final PV value was 'INVALID' (type: 'str')
]]></failure>
	</testcase>
</testsuite>
