<?xml version="1.0" encoding="UTF-8"?>
<testsuite name="tests.pearlpc.PEARLPCTests-20210728092544" tests="2" file="tests/pearlpc.py" time="22.508" timestamp="2021-07-28T09:26:19" failures="1" errors="0" skipped="0">
	<testcase classname="tests.pearlpc.PEARLPCTests" name="test_WHEN_pressure_set_THEN_pressure_readback_correctly" time="0.786" timestamp="2021-07-28T09:26:19" file="tests\pearlpc.py" line="36"/>
	<testcase classname="tests.pearlpc.PEARLPCTests" name="test_WHEN_max_pressure_set_THEN_max_pressure_set_correctly" time="21.721" timestamp="2021-07-28T09:26:19" file="tests\pearlpc.py" line="39">
		<failure type="AssertionError" message="PV TE:NDLT1544:PEARLPC_01:PRESSURE:SP:SP does not exist"><![CDATA[Traceback (most recent call last):
  File "C:\Instrument\Apps\EPICS\support\PearlPressureContainer\master\system_tests\tests\pearlpc.py", line 41, in test_WHEN_max_pressure_set_THEN_max_pressure_set_correctly
    self.ca.assert_setting_setpoint_sets_readback(pressure_mx, "PRESSURE:SP")
  File "C:\Instrument\Apps\EPICS\support\IocTestFramework\master\utils\channel_access.py", line 553, in assert_setting_setpoint_sets_readback
    self.set_pv_value(set_point_pv, value, sleep_after_set=0)
  File "C:\Instrument\Apps\EPICS\support\IocTestFramework\master\utils\channel_access.py", line 119, in set_pv_value
    self.assert_that_pv_exists(pv)
  File "C:\Instrument\Apps\EPICS\support\IocTestFramework\master\utils\channel_access.py", line 482, in assert_that_pv_exists
    raise AssertionError("PV {pv} does not exist".format(pv=pv))
AssertionError: PV TE:NDLT1544:PEARLPC_01:PRESSURE:SP:SP does not exist
]]></failure>
	</testcase>
</testsuite>
